Workbook

Sheet 1. Inputs
A1: Adobe Inc. (ADBE) — MODEL INPUTS
A2: Every hard-coded number in this workbook lives on this sheet. Sheets 2 and 3 contain formulas only.
A3: AMBER = judgment / assumption input (change me). BLUE = reported actual from a primary source (fixed). White = formula.
B4: AMBER | C4: BLUE
A6: CONTENTS: A. Valuation, tax and policy scalars | B. Scenario probabilities and terminal multiples | C. Equity bridge (Q2 FY2026 balance sheet) | D. Off-balance-sheet hosting obligations | E. Shared forecast assumptions | F. Scenario drivers | G. Interim actuals for the TTM build
A8: A. VALUATION, TAX AND POLICY SCALARS
A9: Discount rate (r) | B9: 0.15 | K9: valuation.md §2 / §5.2: 'The discount rate is a stated variable, not a fitted one' — set at 15% per the brief, not derived from CAPM/WACC. valuation_calcs.py DISCOUNT_RATE.
A10: Normalised tax rate | B10: 0.21 | K10: owners_earnings_and_roic.md §2.3: '21% ... approximately the U.S. federal statutory rate, sits within a point of the FY2023-FY2026E average GAAP ETR of 20.1% ... between the two converging measures.' GAAP ETR 18-23%, cash rate 25-27%. JUDGMENT. Sensitivity there: 18% -> TTM OE $7,775M; 25% -> $7,111M.
A11: Discount rate for PV of purchase obligations | B11: 0.05 | K11: owners_earnings_calcs.py DISC (§5). JUDGMENT: roughly Adobe's marginal borrowing cost.
A12: Operating cash need, % of revenue | B12: 0.02 | K12: owners_earnings_and_roic.md §4: 'Adobe collects in advance and runs negative working capital, so its genuine operating cash requirement is small ... This is an assumption, not a sourced figure.' owners_earnings_calcs.py OPERATING_CASH_PCT.
A13: Terminal ROIC on incremental capital (Gordon cross-check only) | B13: 0.7 | K13: terminal_value.md §6.1 uses ROIC ~70% in the reinvestment drag term (1 - g/ROIC). owners_earnings_and_roic.md §1 reports TTM ROIC 72.0% (base) with a 43-45% conservative floor. Feeds the sheet-3 Gordon grid only — it does not affect the headline valuation.
A15: B. SCENARIO PROBABILITIES AND TERMINAL MULTIPLES
B16: Probability | C16: Terminal x | K16: Probabilities: forecast_earnings.md §1 — 'my judgment and are not sourced'. Terminal multiples: terminal_value.md §6.2 — ANALYST JUDGMENT, cross-checked against the Gordon grid and peer multiples on sheet 3.
A17: SEVERE | B17: 0.15 | C17: 7 | K17: terminal_value.md §6.2: terminal decline, AI substitutes the workflow. Gordon at g=-3%, r=10% -> 8.0x. Market precedent ZM 9.0x; SSTK 0.23x sales after a -70% year.
A18: BEAR | B18: 0.25 | C18: 11 | K18: terminal_value.md §6.2: grinding share loss, ~0-1% perpetual growth. Gordon at g=0-1%, r=9-10% -> 10.0x-12.3x. Floor cohort DBX 19.7x, GEN 18.0x, ZM 9.0x.
A19: BASE | B19: 0.4 | C19: 15 | K19: terminal_value.md §6.2: ~3% perpetual growth, 'the world where the question is neither resolved nor realised, so 15x — near today's actual and between the two peer cohorts — is the internally consistent choice.' Gordon at g=3%, r=9% -> 16.0x.
A20: BULL | B20: 0.2 | C20: 22 | K20: terminal_value.md §6.2: franchise durable, AI net accretive. Gordon at g=4%, r=8.5% ~ 21x. Mature-software median 27.2x; ADSK 33.8x. Set BELOW both.
A21: check: probabilities sum to 100% | B21: =SUM(B17:B20)
A23: C. EQUITY BRIDGE — Q2 FY2026 BALANCE SHEET (period ended 29 May 2026)
A24: Cash and cash equivalents | B24: 4919 | K24: primary_sources/2Q2026/financial_statements.md, consolidated balance sheet.
A25: Short-term investments | B25: 707 | K25: primary_sources/2Q2026/financial_statements.md, consolidated balance sheet.
A26: Debt, current (incl. $494M commercial paper), carrying value | B26: 1843 | K26: primary_sources/2Q2026/financial_statements.md, consolidated balance sheet. Commercial paper drawn $494M — 10-Q Note 14.
A27: Debt, long-term (senior notes), carrying value | B27: 4802 | K27: primary_sources/2Q2026/financial_statements.md, consolidated balance sheet.
A28: Operating lease liabilities, current | B28: 91 | K28: primary_sources/2Q2026/financial_statements.md, consolidated balance sheet.
A29: Operating lease liabilities, long-term | B29: 329 | K29: primary_sources/2Q2026/financial_statements.md, consolidated balance sheet.
A30: Shares outstanding, spot at 29 May 2026 (M) | B30: 399 | K30: primary_sources/2Q2026/financial_statements.md, consolidated balance sheet. A point-in-time count.
A31: Current dilutive effect of stock plans (M) | B31: 0.1 | K31: 10-Q Note 12: three-months-ended diluted w.a. 402.5M less basic w.a. 402.4M. Small because 12.1M potential shares are currently anti-dilutive.
A32: = Current diluted share count (M) | B32: =B30+B31 | K32: valuation.md §3 = 399.1M. Per the brief this is TODAY's share count: no forecast buyback shrinkage (notably NOT the FY2030E 341M in forecast_earnings.md §8). The 402.5M three-month weighted average was rejected as backward-looking and stale while Adobe repurchases continuously.
A34: D. OFF-BALANCE-SHEET HOSTING / DATA-CENTRE PURCHASE OBLIGATIONS
A35: $6,821M of non-cancellable unconditional purchase obligations 'primarily relating to contracts with vendors for third-party hosting and data center services' (owners_earnings_and_roic.md §4.1).
A36: FY2026 contractual obligation | B36: 2083 | K36: primary_sources/FY2025/financial_statements.md Note 16 maturity schedule; owners_earnings_calcs.py §5.
A37: FY2027 contractual obligation | B37: 1901
A38: FY2028 contractual obligation | B38: 1623
A39: FY2029 contractual obligation | B39: 1196
A40: FY2030 contractual obligation | B40: 12
A41: FY2031 contractual obligation | B41: 6
A42: Undiscounted total | B42: =SUM(B36:B41)
A43: = Present value, mid-year convention | B43: =SUMPRODUCT(B36:B41/(1+$B$11)^(ROW(B36:B41)-ROW($B$36)+0.5)) | K43: owners_earnings_and_roic.md §4.1 reports $6,259M at 5%. pv = SUM( v / 1.05^(i+0.5) ), i = 0..5 — owners_earnings_calcs.py §5.
A45: E. SHARED FORECAST ASSUMPTIONS (identical in all four scenarios)
F46: FY2026E | G46: FY2027E | H46: FY2028E | I46: FY2029E | J46: FY2030E | K46: forecast_earnings.md §8 — the lines that do not vary by scenario.
...

Sheet 2. Owners Earnings
A1: Adobe Inc. (ADBE) — OWNERS' EARNINGS: HISTORICAL AND PROJECTED ($M)
A2: Historical actuals (columns B-E) and the BASE-case forecast (columns F-J) are built on ONE identical construction, so the columns are directly comparable left to right. The other three scenarios run the same engine in §6 and are summarised in §7.
A3: AMBER = judgment input (all on sheet 1) BLUE = reported actual from a primary source GREEN = headline output white = formula
A4: CONTENTS: §1 The owners' earnings bridge (the answer) | §2 Supporting detail for the historical adjustments | §3 Reported income statement and the TTM build | §4 Customer-group revenue, the forecast's starting base | §5 Forecast build, BASE case | §6 The other three scenario engines | §7 Owners' earnings by scenario | §8 Checks
A6: ($M unless noted) | B6: FY2023A | C6: FY2024A | D6: FY2025A | E6: TTM Q2FY26 | F6: FY2026E | G6: FY2027E | H6: FY2028E | I6: FY2029E | J6: FY2030E | K6: CAGR FY23-25 | L6: CAGR FY25-30E | M6: Source / note
A8: §1. THE OWNERS' EARNINGS BRIDGE — HISTORICAL ACTUAL AND PROJECTED, SIDE BY SIDE
A9: EBIT + non-recurring charges + purchased-intangible amortisation = EBITA; + PP&E depreciation − maintenance capex = pre-tax owners' earnings; x (1 − normalised tax rate) = OWNERS' EARNINGS. Stock-based compensation is deliberately NOT added back — it is a real cost to owners and stays inside EBIT (owners_earnings_and_roic.md §2.1).
A11: TOTAL REVENUE (memo) | B11: =B53 | C11: =C53 | D11: =D53 | E11: =E53 | F11: =F92 | G11: =G92 | H11: =H92 | I11: =I92 | J11: =J92 | K11: =IFERROR((D11/B11)^(1/2)-1,"") | L11: =IFERROR((J11/D11)^(1/5)-1,"") | M11: Historical from §3; forecast from §5. Shown here only to compute margins.
A13: Operating income (EBIT) | B13: =B63 | C13: =C63 | D13: =D63 | E13: =E63 | F13: =F105-'1. Inputs'!F$53 | G13: =G105-'1. Inputs'!G$53 | H13: =H105-'1. Inputs'!H$53 | I13: =I105-'1. Inputs'!I$53 | J13: =J105-'1. Inputs'!J$53 | M13: Historical: as reported (§3). Forecast: DERIVED as driver-built EBITA (§5) less Adobe's own disclosed forward amortisation schedule (sheet 1 §E), which excludes future acquisitions and is therefore a floor on amortisation.
A14: + non-recurring charges booked in operating expenses | B14: =B40 | C14: =C40 | D14: =D40 | E14: =E40 | F14: ='1. Inputs'!F$54 | G14: ='1. Inputs'!G$54 | H14: ='1. Inputs'!H$54 | I14: ='1. Inputs'!I$54 | J14: ='1. Inputs'!J$54 | M14: Detail in §2. FY2024 $1,078M = $1,000M Figma termination fee + $78M lease impairments; TTM $162M = $70M goodwill impairment + $92M FTC loss contingency, both booked in 1H FY2026 so neither is rolled (owners_earnings_calcs.py §3).
A15: + amortisation of purchased intangibles | B15: 375 | C15: 336 | D15: 310 | E15: =D15-'1. Inputs'!$B$131+'1. Inputs'!$C$131 | F15: ='1. Inputs'!F$53 | G15: ='1. Inputs'!G$53 | H15: ='1. Inputs'!H$53 | I15: ='1. Inputs'!I$53 | J15: ='1. Inputs'!J$53 | M15: FY2025 10-K Note 8 / Q2 FY2026 10-Q Note 7. Added back because the acquired asset base is maintained by R&D and S&M that are already expensed inside EBIT, while the capital itself stays in invested capital.
A16: = EBITA | B16: =B13+B14+B15 | C16: =C13+C14+C15 | D16: =D13+D14+D15 | E16: =E13+E14+E15 | F16: =F13+F14+F15 | G16: =G13+G14+G15 | H16: =H13+H14+H15 | I16: =I13+I14+I15 | J16: =J13+J14+J15 | K16: =IFERROR((D16/B16)^(1/2)-1,"") | L16: =IFERROR((J16/D16)^(1/5)-1,"") | M16: Earnings before interest, tax and purchased-intangible amortisation — the basis owners' earnings is built on.
A17: EBITA margin | B17: =B16/B11 | C17: =C16/C11 | D17: =D16/D11 | E17: =E16/E11 | F17: =F16/F11 | G17: =G16/G11 | H17: =H16/H11 | I17: =I16/I11 | J17: =J16/J11
A18: + PP&E depreciation | B18: 235 | C18: 239 | D18: 236 | E18: 236 | F18: =$D18*(1+'1. Inputs'!$B$59)^1 | G18: =$D18*(1+'1. Inputs'!$B$59)^2 | H18: =$D18*(1+'1. Inputs'!$B$59)^3 | I18: =$D18*(1+'1. Inputs'!$B$59)^4 | J18: =$D18*(1+'1. Inputs'!$B$59)^5 | M18: FY2025 10-K Note 6. TTM is NOT rolled: depreciation is not separately disclosed in the 10-Q and net PP&E is essentially unchanged ($1,873M -> $1,870M), so FY2025's $236M is carried (owners_earnings_calcs.py §3).
A19: − maintenance capex | B19: =-AVERAGE($B42:$D42) | C19: =-AVERAGE($B42:$D42) | D19: =-AVERAGE($B42:$D42) | E19: =-AVERAGE($B42:$D42) | F19: =-'1. Inputs'!$B$60*(1+'1. Inputs'!$B$61)^1 | G19: =-'1. Inputs'!$B$60*(1+'1. Inputs'!$B$61)^2 | H19: =-'1. Inputs'!$B$60*(1+'1. Inputs'!$B$61)^3 | I19: =-'1. Inputs'!$B$60*(1+'1. Inputs'!$B$61)^4 | J19: =-'1. Inputs'!$B$60*(1+'1. Inputs'!$B$61)^5 | M19: 3-year average of ACTUAL capex FY2023-FY2025 (§2) = $240.7M, applied to every historical period; grown 5%/yr in the forecast off the rounded $241M base on sheet 1. owners_earnings_and_roic.md §2.2 — 'Using one year's depressed capex would flatter owners' earnings.'
A20: = pre-tax owners' earnings | B20: =B16+B18+B19 | C20: =C16+C18+C19 | D20: =D16+D18+D19 | E20: =E16+E18+E19 | F20: =F16+F18+F19 | G20: =G16+G18+G19 | H20: =H16+H18+H19 | I20: =I16+I18+I19 | J20: =J16+J18+J19
A21: − normalised tax | B21: =-B20*'1. Inputs'!$B$10 | C21: =-C20*'1. Inputs'!$B$10 | D21: =-D20*'1. Inputs'!$B$10 | E21: =-E20*'1. Inputs'!$B$10 | F21: =-F20*'1. Inputs'!$B$10 | G21: =-G20*'1. Inputs'!$B$10 | H21: =-H20*'1. Inputs'!$B$10 | I21: =-I20*'1. Inputs'!$B$10 | J21: =-J20*'1. Inputs'!$B$10 | M21: At the single normalised rate on sheet 1 §A (21%), applied identically to every period and every scenario.
A22: = OWNERS' EARNINGS | B22: =B20+B21 | C22: =C20+C21 | D22: =D20+D21 | E22: =E20+E21 | F22: =F20+F21 | G22: =G20+G21 | H22: =H20+H21 | I22: =I20+I21 | J22: =J20+J21 | K22: =IFERROR((D22/B22)^(1/2)-1,"") | L22: =IFERROR((J22/D22)^(1/5)-1,"") | M22: Method A, owners_earnings_and_roic.md §1-§2. Forecast columns are the BASE case; §7 shows all four scenarios.
A23: owners' earnings margin (% of revenue) | B23: =B22/B11 | C23: =C22/C11 | D23: =D22/D11 | E23: =E22/E11 | F23: =F22/F11 | G23: =G22/G11 | H23: =H22/H11 | I23: =I22/I11 | J23: =J22/J11
A24: owners' earnings growth, year on year | C24: =C22/B22-1 | D24: =D22/C22-1 | F24: =F22/D22-1 | G24: =G22/F22-1 | H24: =H22/G22-1 | I24: =I22/H22-1 | J24: =J22/I22-1 | M24: No growth is shown for the TTM column: it overlaps FY2025 and is not a clean year-on-year comparison. FY2026E growth is struck off FY2025A.
A26: NO forecast share count, buyback path or forecast owners' earnings per share is modelled anywhere in this workbook. Projecting them requires stacking three further judgment assumptions — a buyback payout ratio, a stock-based compensation ratio, and an assumed repurchase PRICE — and the price assumption is circular with the valuation the model is trying to produce. The valuation on sheet 3 uses TODAY's diluted share count of 399.1M throughout, per the brief (valuation.md §3), so none of it would change the answer. Adobe's actual buyback pace is shown below as history only.
A27: memo: stock-based compensation (deducted inside EBIT, never added back) | B27: 1718 | C27: 1833 | D27: 1942 | E27: =D27-'1. Inputs'!$B$134+'1. Inputs'!$C$134 | M27: FY2025 10-K Note 12. Cross-checked against shares actually delivered: 4.8M shares at a ~$408 weighted-average grant-date fair value ~ $1,920M against the $1,942M GAAP charge, within ~1% (owners_earnings_and_roic.md §2.1).
A28: memo: diluted shares (M) — HISTORICAL ONLY | B28: 459.1 | C28: 449.7 | D28: 427 | E28: =D28-'1. Inputs'!$B$135+'1. Inputs'!$C$135 | M28: owners_earnings_calcs.py §7. TTM uses the same TTM convention: 427.0 − 433.2 + 406.6 = 400.4M. NO forecast share count is modelled — see the note below.
A29: memo: OWNERS' EARNINGS PER DILUTED SHARE — HISTORICAL ONLY | B29: =B22/B28 | C29: =C22/C28 | D29: =D22/D28 | E29: =E22/E28 | K29: =IFERROR((D29/B29)^(1/2)-1,"") | M29: owners_earnings_and_roic.md §1: $12.08 / $14.32 / $16.67 / $18.71. Reported actuals divided by reported share counts — no assumption in them.
A30: memo: buyback spend, ACTUAL — HISTORICAL ONLY | B30: 4400 | C30: 9500 | D30: 11281 | M30: owners_earnings_and_roic.md §5; 1H FY2026 spend was $4,589M. Shown as history, not extrapolated.
A31: actual buyback as a multiple of owners' earnings | B31: =B30/B22 | C31: =C30/C22 | D31: =D30/D22 | M31: Adobe repurchased at ~1.5-1.6x owners' earnings in FY2024-FY2025 — it spent more than it earned. terminal_value.md §9 flags that if that pace continues 'the equity bridge stops being immaterial'. That is a stated RISK to the sheet-3 bridge, not a modelled forecast.
A33: §2. SUPPORTING DETAIL FOR THE HISTORICAL OWNERS' EARNINGS ADJUSTMENTS
A34: Every add-back used in §1, itemised and sourced. This is the audit trail for the historical bridge.
A36: Figma acquisition termination fee | B36: 0 | C36: =C62 | D36: 0 | E36: 0 | M36: FY2024 one-off, $1,000M, disclosed on its own income-statement line (primary_sources/FY2025/md_and_a.md). Pulled from §3 so it cannot drift.
A37: Lease-related asset impairments | B37: 0 | C37: 78 | D37: 0 | E37: 0 | M37: FY2024, $78M — FY2025 10-K cash-flow statement; Note 7 places the charge in G&A. owners_earnings_and_roic.md §2.1.
A38: Goodwill impairment, Publishing & Advertising | B38: 0 | C38: 0 | D38: 0 | E38: ='1. Inputs'!$C$132 | M38: $70M, Q2 FY2026 10-Q Note 7. Booked in 1H FY2026, so it enters the TTM column directly and is NOT rolled through the FY25 − 1H25 + 1H26 formula.
A39: FTC/DOJ ROSCA loss contingency accrual | B39: 0 | C39: 0 | D39: 0 | E39: ='1. Inputs'!$C$133 | M39: $92M, 1H FY2026. Same treatment as the goodwill impairment above.
A40: = total non-recurring charges added back in §1 | B40: =SUM(B36:B39) | C40: =SUM(C36:C39) | D40: =SUM(D36:D39) | E40: =SUM(E36:E39) | M40: FY2023 $0M, FY2024 $1,078M, FY2025 $0M ('none in FY2025'), TTM $162M — owners_earnings_and_roic.md §2.1.
A42: memo: capital expenditure, ACTUAL | B42: 360 | C42: 183 | D42: 179 | E42: 201 | M42: FY2025 10-K and Q2 FY2026 10-Q cash-flow statements. Net PP&E has been SHRINKING ($1,936M -> $1,873M -> $1,870M), i.e. recent capex runs below depreciation — which is why a 3-year average, not the latest year, is used as maintenance capex.
A43: 3-year average actual capex FY2023-FY2025 ( = maintenance capex applied to every historical period) | B43: =AVERAGE(B42:D42) | M43: $240.667M. owners_earnings_and_roic.md §2.2 notes this 'lands within $5M of FY2025 depreciation, a useful independent confirmation that it is the right order of magnitude'. Sensitivity there: +/-$60M of capex moves owners' earnings by ~$47M after tax, ~0.6%.
A45: NOT adjusted, deliberately: (a) stock-based compensation is a real cost to owners and stays inside EBIT; (b) the $6,821M of hosting purchase obligations are contracted OPERATING spend already flowing through cost of revenue as incurred, so adding a charge would double-count — they are instead treated as a debt-like item in the equity bridge on sheet 3; (c) the deferred-revenue float is not counted as earnings. owners_earnings_and_roic.md §2.1, §4.1.
A47: §3. REPORTED INCOME STATEMENT — THE SOURCE OF THE EBIT LINE IN §1
A48: FY2023A-FY2025A as reported. The TTM Q2 FY2026 column is built as FY2025 − 1H FY2025 + 1H FY2026 from the interim actuals on sheet 1 §G.
A50: Subscription revenue | B50: 18284 | C50: 20521 | D50: 22904 | E50: =D50-'1. Inputs'!$B$120+'1. Inputs'!$C$120 | M50: primary_sources/FY2025/financial_statements.md, Consolidated Statements of Income.
A51: Product revenue | B51: 460 | C51: 386 | D51: 325 | E51: =D51-'1. Inputs'!$B$121+'1. Inputs'!$C$121
...

Sheet 3. Terminal Value and SOTP
A1: Adobe Inc. (ADBE) — TERMINAL VALUE AND SUM-OF-THE-PARTS VALUATION
A2: Value = PV(forecast owners' earnings) + PV(terminal value) + standalone assets − all debt-like items, divided by TODAY's diluted share count. The valuation is trading-price blind: Adobe's share price and market capitalisation are not an input anywhere on this sheet (valuation.md §0, §2).
A3: CONTENTS: §A Headline sum of the parts | §B Terminal value by scenario | §C Gordon cross-check on the terminal multiples | §D Discounting | §E Full valuation by scenario | §F Equity bridge | §G Sensitivity | §H Checks
A5: §A. HEADLINE — SUM OF THE PARTS, PROBABILITY-WEIGHTED
A7: Part 1 PV of explicit-period owners' earnings, FY2026E-FY2030E (t=0..4) | B7: =F51 | H7: Detail in §E. Each scenario's own owners'-earnings path from sheet 2 §7, discounted at the rate on sheet 1.
A8: Part 2 PV of terminal value at FY2030 year-end (t=4) | B8: =F52 | H8: Detail in §B and §E.
A9: = ENTERPRISE VALUE | B9: =B7+B8 | H9: An ENTERPRISE value, because owners' earnings are unlevered: interest expense and interest income sit below the operating line and are excluded (terminal_value.md §2).
A10: Part 3 + Standalone assets (excess cash and short-term investments) | B10: =B68
A11: Part 4 − Total debt-like items | B11: =-B75 | H11: Funded debt + operating leases + the PV of off-balance-sheet hosting commitments. Detail and alternative conventions in §F and §G(ii).
A12: = EQUITY VALUE | B12: =B9+B10+B11
A13: ÷ diluted shares outstanding (M) | B13: ='1. Inputs'!$B$32
A14: = INTRINSIC VALUE PER DILUTED SHARE | B14: =B12/B13 | H14: valuation.md §1. The probability-weighted headline. §E shows the same walk for each scenario separately — the range is roughly 4.7x from least to most favourable, which is the honest measure of how open the question is.
A16: memo: terminal value as % of enterprise value | B16: =B8/B9 | H16: ~72%. The answer is dominated by the terminal multiple, not by the five-year forecast. terminal_value.md §1 also flags that 38% of the probability-weighted terminal value comes from the 20%-probability bull case.
A18: §B. TERMINAL VALUE AT FY2030 YEAR-END, BY SCENARIO (undiscounted, enterprise basis)
A20: ($M unless noted) | B20: SEVERE | C20: BEAR | D20: BASE | E20: BULL | F20: WEIGHTED
A21: Probability | B21: ='1. Inputs'!$B$17 | C21: ='1. Inputs'!$B$18 | D21: ='1. Inputs'!$B$19 | E21: ='1. Inputs'!$B$20 | F21: =SUM(B21:E21) | H21: From sheet 1 §B. The WEIGHTED column here is the check that they sum to 100%.
A22: FY2030E owners' earnings | B22: ='2. Owners Earnings'!J178 | C22: ='2. Owners Earnings'!J179 | D22: ='2. Owners Earnings'!J180 | E22: ='2. Owners Earnings'!J181 | F22: ='2. Owners Earnings'!J182 | H22: Sheet 2 §7 — the end point of each scenario's owners'-earnings path.
A23: Terminal multiple (x FY2030E owners' earnings) | B23: ='1. Inputs'!$C$17 | C23: ='1. Inputs'!$C$18 | D23: ='1. Inputs'!$C$19 | E23: ='1. Inputs'!$C$20 | F23: =F25/F22 | H23: ANALYST JUDGMENT (terminal_value.md §6.2), cross-checked in §C. Each multiple is applied to ITS OWN scenario's earnings; a multiple is never applied to blended earnings. The WEIGHTED cell is therefore an OUTPUT — the multiple implied by the weighted terminal value divided by the weighted FY2030E earnings ( = 15.3x, terminal_value.md §1). Note this is NOT the probability-weighted average of the four multiples, which is 14.2x: the higher-earnings scenarios also carry the higher multiples, so the implied multiple exceeds the simple mean.
A24: memo: probability-weighted AVERAGE of the four multiples | F24: =B21*B23+C21*C23+D21*D23+E21*E23 | H24: Shown only to make the distinction above explicit. This figure is NOT used anywhere in the valuation.
A25: TERMINAL VALUE at FY2030 year-end | B25: =B23*B22 | C25: =C23*C22 | D25: =D23*D22 | E25: =E23*E22 | F25: =B21*B25+C21*C25+D21*D25+E21*E25 | H25: terminal_value.md §1: $42.2bn / $89.2bn / $161.2bn / $286.8bn, weighted $150.4bn. Applying a single 15x to weighted earnings instead would give $147.5bn, 'only 1.9% away' — the weighting method is not doing the work.
A26: share of the weighted terminal value | B26: =B21*B25/$F25 | C26: =C21*C25/$F25 | D26: =D21*D25/$F25 | E26: =E21*E25/$F25 | H26: terminal_value.md §1. Note the bull case supplies ~38% of the weighted terminal value on a 20% probability — the single largest concentration of judgment in the valuation.
A28: §C. CROSS-CHECK ON THE TERMINAL MULTIPLES — GORDON PERPETUITY GRID
A29: Value / owners' earnings = (1 − g / ROIC) / (r − g). The (1 − g/ROIC) term is the reinvestment drag: growth is not free, it must be funded out of earnings. terminal_value.md §6.1 runs this grid at ROIC ~70% (sheet 1 §A) and rejects a third-party 11.53% WACC as too high, using an 8-10% band instead. This grid is a SANITY CHECK on the judgment multiples in §B — it does not feed the valuation.
A31: perpetual growth g \ discount rate r | B31: 0.08 | C31: 0.09 | D31: 0.1 | E31: 0.11
A32: -0.03 | B32: =(1-$A32/'1. Inputs'!$B$13)/(B$31-$A32) | C32: =(1-$A32/'1. Inputs'!$B$13)/(C$31-$A32) | D32: =(1-$A32/'1. Inputs'!$B$13)/(D$31-$A32) | E32: =(1-$A32/'1. Inputs'!$B$13)/(E$31-$A32) | H32: Read against §B: SEVERE 7x sits below the g=-3% row; BEAR 11x between g=0% and g=1%; BASE 15x just under the g=3%, r=9% cell (16.0x); BULL 22x just above g=4%, r=8.5%. Each judgment multiple is therefore internally consistent with a plausible (g, r) pair rather than picked freehand.
A33: 0 | B33: =(1-$A33/'1. Inputs'!$B$13)/(B$31-$A33) | C33: =(1-$A33/'1. Inputs'!$B$13)/(C$31-$A33) | D33: =(1-$A33/'1. Inputs'!$B$13)/(D$31-$A33) | E33: =(1-$A33/'1. Inputs'!$B$13)/(E$31-$A33)
A34: 0.01 | B34: =(1-$A34/'1. Inputs'!$B$13)/(B$31-$A34) | C34: =(1-$A34/'1. Inputs'!$B$13)/(C$31-$A34) | D34: =(1-$A34/'1. Inputs'!$B$13)/(D$31-$A34) | E34: =(1-$A34/'1. Inputs'!$B$13)/(E$31-$A34)
A35: 0.02 | B35: =(1-$A35/'1. Inputs'!$B$13)/(B$31-$A35) | C35: =(1-$A35/'1. Inputs'!$B$13)/(C$31-$A35) | D35: =(1-$A35/'1. Inputs'!$B$13)/(D$31-$A35) | E35: =(1-$A35/'1. Inputs'!$B$13)/(E$31-$A35)
A36: 0.03 | B36: =(1-$A36/'1. Inputs'!$B$13)/(B$31-$A36) | C36: =(1-$A36/'1. Inputs'!$B$13)/(C$31-$A36) | D36: =(1-$A36/'1. Inputs'!$B$13)/(D$31-$A36) | E36: =(1-$A36/'1. Inputs'!$B$13)/(E$31-$A36)
A37: 0.04 | B37: =(1-$A37/'1. Inputs'!$B$13)/(B$31-$A37) | C37: =(1-$A37/'1. Inputs'!$B$13)/(C$31-$A37) | D37: =(1-$A37/'1. Inputs'!$B$13)/(D$31-$A37) | E37: =(1-$A37/'1. Inputs'!$B$13)/(E$31-$A37)
A39: Peer anchors at 31 Aug 2026 (fetched_docs/peer_multiples_compare_2026.md, terminal_value.md §5): mature large-cap software trailing P/E median 27.2x (MSFT 28.6x, SAP 28.8x, ORCL 25.9x, CRM 23.7x, INTU 21.8x, ADSK 33.8x); ex-growth / disruption-discounted median 18.8x (DBX 19.7x, GEN 18.0x, ZM 9.0x, DOCU 41.6x). ADBE itself trades at 16.7x trailing owners' earnings, a 59% de-rating from its own FY2021-FY2025 median of 40.9x. Peer P/Es are read directly against owners'-earnings multiples because TTM owners' earnings ($7,490M) sit only 3.6% above TTM GAAP net income ($7,230M) — terminal_value.md §2.
A41: §D. DISCOUNTING
A42: valuation.md §2: the current fiscal year is t=0 and is NOT discounted. As of the 1 Sep 2026 valuation date Adobe is inside FY2026, so FY2026E = t=0. The terminal value is the value of the business AT THE END of FY2030, realised at the same moment as the FY2030 flow, so it is discounted at the same t=4 factor — not t=5.
A44: ($M unless noted) | B44: FY2026E | C44: FY2027E | D44: FY2028E | E44: FY2029E | F44: FY2030E
A45: t (years discounted) | B45: 0 | C45: 1 | D45: 2 | E45: 3 | F45: 4
A46: Discount factor = 1 / (1 + r)^t | B46: =1/(1+'1. Inputs'!$B$9)^B45 | C46: =1/(1+'1. Inputs'!$B$9)^C45 | D46: =1/(1+'1. Inputs'!$B$9)^D45 | E46: =1/(1+'1. Inputs'!$B$9)^E45 | F46: =1/(1+'1. Inputs'!$B$9)^F45 | H46: r is the single input at sheet 1 cell B9. At 15% the factors are 1.0000 / 0.8696 / 0.7561 / 0.6575 / 0.5718.
A48: §E. FULL VALUATION BY SCENARIO — the four 'parts' behind the headline
A50: ($M unless noted) | B50: SEVERE | C50: BEAR | D50: BASE | E50: BULL | F50: WEIGHTED
A51: Part 1 PV of owners' earnings, FY2026E-FY2030E | B51: =SUMPRODUCT('2. Owners Earnings'!$F$178:$J$178,$B46:$F46) | C51: =SUMPRODUCT('2. Owners Earnings'!$F$179:$J$179,$B46:$F46) | D51: =SUMPRODUCT('2. Owners Earnings'!$F$180:$J$180,$B46:$F46) | E51: =SUMPRODUCT('2. Owners Earnings'!$F$181:$J$181,$B46:$F46) | F51: =SUMPRODUCT('2. Owners Earnings'!$F$182:$J$182,$B46:$F46) | H51: Each scenario's own owners'-earnings path (sheet 2 §7) times the discount factors in §D.
A52: Part 2 PV of terminal value (discounted at t=4) | B52: =B25*$F46 | C52: =C25*$F46 | D52: =D25*$F46 | E52: =E25*$F46 | F52: =F25*$F46 | H52: The terminal values from §B brought back four years.
...
