Workbook

Sheet Inputs
B1: NamSys Inc. (TSXV: CTZ) -- valuation model INPUTS
B2: All Canadian dollars. Fiscal year ends October 31. Every cell shaded BEIGE with BLUE BOLD text is a hard-coded input; change it and the whole model re-computes. Black cells are formulas. Column Q carries the source for each input.
B4: LEGEND: | C4: input | D4: = editable input
B6: 1. VALUATION ASSUMPTIONS (VAL s1)
B7: Discount rate (r) | C7: 0.1 | Q7: VAL s1 DISCOUNT_RATE -- set by the brief, not independently derived; sensitised on the Valuation sheet
B8: Diluted shares outstanding | C8: 27459593 | Q8: MDQ2 line 114: weighted-average diluted shares, 3 months ended Apr 30 2026
B9: Cross-check: H1 FY2026 diluted shares | C9: 27498422 | Q9: FSQ2 line 85: six months ended Apr 30 2026 (used only as a cross-check)
B10: Cash at April 30, 2026 | C10: 940082 | Q10: FSQ2 balance sheet / OE s4
B11: Short-term investments at April 30, 2026 | C11: 6425965 | Q11: FSQ2 balance sheet (cashable GICs) / OE s4
B12: Debt | C12: 0 | Q12: OE s2 pt1, quoting FY2025 MD&A: 'the Company has no debt outstanding'
B13: Contingent employee termination commitment | C13: 1100000 | Q13: FS25 Note 13 / OE s3.1 -- payable only on termination without cause
B14: Treat that commitment as debt? (1 = yes, 0 = no) | C14: 0 | Q14: VAL s3.3/s5 -- base case is 0 (contingent, not a certain obligation)
B15: = Standalone assets (cash + short-term investments) | C15: =$C$10+$C$11 | Q15: VAL s3.3 CASH_AND_STI_APR26 = 940,082 + 6,425,965
B16: = Total debt-like deduction | C16: =$C$12+$C$14*$C$13
B17: Scenario shown on the 'Owners Earnings' sheet | C17: 1 | D17: 1 = Base, 2 = Bull, 3 = Bear (no cost response), 4 = Bear (right-sizes)
B19: 2. TERMINAL MULTIPLE ON FY2030E OWNERS' EARNINGS (TV s5/s6)
B20: Low end of defensible range | C20: 9 | Q20: TV s6 MULT_LOW -- mature low-growth microcap software cluster (TV s3)
B21: Base case | C21: 12 | Q21: TV s6 MULT_BASE -- high quality (99% recurring, ~40% margin, no debt) offset by 37-39% top-3 concentration (TV s3.1/s3.2)
B22: High end of defensible range | C22: 15 | Q22: TV s6 MULT_HIGH -- high-margin microcap software / take-private cluster
B23: Bear scenarios (both variants) | C23: 8 | Q23: TV s6 diagonal -- the multiple co-moves with the scenario
B24: Scenario-consistent multiple: Bull | C24: =$C$22 | Q24: TV s6: bull pairs with 15x
B26: 3. NORMALISATION AND TAX CONSTANTS (OE s2)
B27: Statutory tax rate | C27: 0.265 | Q27: MDA25: 'The basic rate of 26.50% was applied'
B28: Normalised bad debt expense (4-yr average) | C28: =AVERAGE(C37:F37) | Q28: OE s2.1 NORM_BAD_DEBT -- simple average of reported FY2022-FY2025 bad debt expense
B29: Normalised share-based compensation (FY2023-FY2025 avg) | C29: =AVERAGE(D38:F38) | Q29: OE s2.1 NORM_SBC -- average of the only three years with a live grant; cross-checks to the Dec-2022 grant fair value of $357,566 over 3 years = $119,189
B30: Forecast other permanent tax difference, per year | C30: 1300 | Q30: FC PERM_DIFF -- Note 9 unexplained residual, FY2025 $1,385 / TTM $1,162 (OE s2.2e); held flat forward
B32: 4. REPORTED HISTORICAL FINANCIALS (all from primary_sources)
B33: TTM Apr-26 = FY2025 + H1 FY2026 - H1 FY2025 (OE script, TTM Period)
C34: FY2022A | D34: FY2023A | E34: FY2024A | F34: FY2025A | M34: H1 FY2025 | N34: H1 FY2026 | O34: TTM Apr-26
B35: Revenue | C35: 5394781 | D35: 6093020 | E35: 6840146 | F35: 7891605 | M35: 3951863 | N35: 4267406 | O35: =F35+N35-M35 | Q35: FS23/FS25/FSQ2 statements of operations
B36: Operating income (reported) | C36: 1753157 | D36: 2107434 | E36: 2572018 | F36: 3146476 | M36: 1626795 | N36: 1779560 | O36: =F36+N36-M36 | Q36: FS23/FS25/FSQ2 -- after bad debt, SBC and depreciation
B37: Bad debt expense (inside operating income) | C37: 2546 | D37: 23004 | E37: 0 | F37: 51330 | M37: 50746 | N37: 0 | O37: =F37+N37-M37 | Q37: FS23/FS24/FS25/FSQ2 expense note
B38: Share-based compensation (inside operating income) | C38: 0 | D38: 191468 | E38: 114174 | F38: 47030 | M38: 27020 | N38: 4894 | O38: =F38+N38-M38 | Q38: FS25 Note 6 / FSQ2 Note 6
B39: Depreciation of property and equipment | C39: 12028 | D39: 7191 | E39: 7023 | F39: 7465 | M39: 3449 | N39: 3623 | O39: =F39+N39-M39 | Q39: FS25 Note 4. FY2022 excludes $10,768 of right-of-use depreciation: that is a real rent cost, not a non-economic charge (OE s2.1)
B40: Purchase of property and equipment (maintenance capex) | C40: 9311 | D40: 4982 | E40: 8259 | F40: 9661 | M40: 3998 | N40: 3595 | O40: =F40+N40-M40 | Q40: FS23/FS25/FSQ2 statements of cash flows -- investing activities
B41: 'Adjustments to determine taxable income' (Note 9) | C41: 1091 | D41: 73248 | E41: 33269 | F41: 13848 | M41: 7932 | N41: 1846 | O41: =F41+N41-M41 | Q41: FS23/FS24/FS25 Note 9 and FSQ2 Note 9 tax-rate reconciliation
B42: Memo: reported net income | C42: 1394440 | D42: 1614875 | E42: 2090475 | F42: 2486109 | M42: 1259346 | N42: 1312064 | O42: =F42+N42-M42 | Q42: FS23/FS25/FSQ2
B43: Memo: interest income (EXCLUDED from owners' earnings) | C43: 5812 | D43: 195112 | E43: 291840 | F43: 265771 | M43: 132073 | N43: 111013 | O43: =F43+N43-M43 | Q43: FS23/FS25/FSQ2 -- excluded per OE s2.2(a); the portfolio is added separately
B44: Memo: FX gain / (loss) (normalised to nil) | C44: 139768 | D44: -5780 | E44: 25590 | F44: -10945 | M44: -34680 | N44: -102941 | O44: =F44+N44-M44 | Q44: FS23/FS25/FSQ2 -- below operating income, normalised to nil (OE s2)
B45: Memo: cash flow from operating activities | C45: 962018 | D45: 1659749 | E45: 2508076 | F45: 2196505 | M45: 1223129 | N45: 1497265 | O45: =F45+N45-M45 | Q45: FS23/FS25/FSQ2. The H1 FY2026 figure of 1,497,265 is the cash already inside the Apr-30-26 balance -- VAL s3.1 nets it out of the t=0 flow
...

Sheet Owners Earnings
B1: NamSys Inc. -- historical and forecast OWNERS' EARNINGS
B2: Columns C:F are reported actuals normalised per owners_earnings_and_roic.md; columns G:K are the driver-based forecast per forecast_earnings.md, shown side by side on the identical bridge. Column M is the TTM memo. The forecast scenario displayed is switched at Inputs!C17.
B4: A. OWNERS' EARNINGS BRIDGE -- HISTORICAL (C:F) AND FORECAST (G:K) SIDE BY SIDE
B5: Owners' earnings = reported operating income, normalised for bad debt and share-based compensation, plus depreciation less maintenance capex, taxed at 26.5% with non-deductible SBC grossed up. Interest income and FX are excluded (OE s2).
C6: FY2022A | D6: FY2023A | E6: FY2024A | F6: FY2025A | G6: FY2026E | H6: FY2027E | I6: FY2028E | J6: FY2029E | K6: FY2030E | M6: TTM Apr-26
B7: Revenue | C7: =Inputs!C35 | D7: =Inputs!D35 | E7: =Inputs!E35 | F7: =Inputs!F35 | G7: =CHOOSE(Inputs!$C$17,G53,G92,G131,G170) | H7: =CHOOSE(Inputs!$C$17,H53,H92,H131,H170) | I7: =CHOOSE(Inputs!$C$17,I53,I92,I131,I170) | J7: =CHOOSE(Inputs!$C$17,J53,J92,J131,J170) | K7: =CHOOSE(Inputs!$C$17,K53,K92,K131,K170) | M7: =Inputs!O35
B8: Revenue growth | D8: =D7/C7-1 | E8: =E7/D7-1 | F8: =F7/E7-1 | G8: =G7/F7-1 | H8: =H7/G7-1 | I8: =I7/H7-1 | J8: =J7/I7-1 | K8: =K7/J7-1
B9: Operating income | C9: =Inputs!C36 | D9: =Inputs!D36 | E9: =Inputs!E36 | F9: =Inputs!F36 | G9: =CHOOSE(Inputs!$C$17,G71,G110,G149,G188) | H9: =CHOOSE(Inputs!$C$17,H71,H110,H149,H188) | I9: =CHOOSE(Inputs!$C$17,I71,I110,I149,I188) | J9: =CHOOSE(Inputs!$C$17,J71,J110,J149,J188) | K9: =CHOOSE(Inputs!$C$17,K71,K110,K149,K188) | M9: =Inputs!O36 | Q9: Actuals: as reported (FS23/FS25/FSQ2). Forecast: built bottom-up in section B below on a NORMALISED cost base
B10: Operating margin | C10: =C9/C7 | D10: =D9/D7 | E10: =E9/E7 | F10: =F9/F7 | G10: =G9/G7 | H10: =H9/H7 | I10: =I9/I7 | J10: =J9/J7 | K10: =K9/K7 | M10: =M9/M7
B12: Adjustments to reach owners' earnings (OE s2.1):
B13: + Reported bad debt expense | C13: =Inputs!C37 | D13: =Inputs!D37 | E13: =Inputs!E37 | F13: =Inputs!F37 | G13: 0 | H13: 0 | I13: 0 | J13: 0 | K13: 0 | M13: =Inputs!O37
B14: - Normalised bad debt expense | C14: =-Inputs!$C$28 | D14: =-Inputs!$C$28 | E14: =-Inputs!$C$28 | F14: =-Inputs!$C$28 | G14: 0 | H14: 0 | I14: 0 | J14: 0 | K14: 0 | M14: =-Inputs!$C$28 | Q14: Zero in the forecast columns by construction: the forecast cost build in section B already charges NORMALISED bad debt and NORMALISED SBC, so there is nothing left to normalise
B15: + Reported share-based compensation | C15: =Inputs!C38 | D15: =Inputs!D38 | E15: =Inputs!E38 | F15: =Inputs!F38 | G15: 0 | H15: 0 | I15: 0 | J15: 0 | K15: 0 | M15: =Inputs!O38
B16: - Normalised share-based compensation | C16: =-Inputs!$C$29 | D16: =-Inputs!$C$29 | E16: =-Inputs!$C$29 | F16: =-Inputs!$C$29 | G16: 0 | H16: 0 | I16: 0 | J16: 0 | K16: 0 | M16: =-Inputs!$C$29
B17: + Depreciation of property and equipment | C17: =Inputs!C39 | D17: =Inputs!D39 | E17: =Inputs!E39 | F17: =Inputs!F39 | G17: =Inputs!$F$39 | H17: =Inputs!$F$39 | I17: =Inputs!$F$39 | J17: =Inputs!$F$39 | K17: =Inputs!$F$39 | M17: =Inputs!O39
B18: - Maintenance capex (actual purchases of PP&E) | C18: =-Inputs!C40 | D18: =-Inputs!D40 | E18: =-Inputs!E40 | F18: =-Inputs!F40 | G18: =-Inputs!$F$40 | H18: =-Inputs!$F$40 | I18: =-Inputs!$F$40 | J18: =-Inputs!$F$40 | K18: =-Inputs!$F$40 | M18: =-Inputs!O40
B19: = Normalised pre-tax owners' earnings | C19: =C9+SUM(C13:C18) | D19: =D9+SUM(D13:D18) | E19: =E9+SUM(E13:E18) | F19: =F9+SUM(F13:F18) | G19: =G9+SUM(G13:G18) | H19: =H9+SUM(H13:H18) | I19: =I9+SUM(I13:I18) | J19: =J9+SUM(J13:J18) | K19: =K9+SUM(K13:K18) | M19: =M9+SUM(M13:M18)
B20: - Normalised tax at the statutory rate on (pre-tax OE + normalised SBC) | C20: =-Inputs!$C$27*(C19+Inputs!$C$29) | D20: =-Inputs!$C$27*(D19+Inputs!$C$29) | E20: =-Inputs!$C$27*(E19+Inputs!$C$29) | F20: =-Inputs!$C$27*(F19+Inputs!$C$29) | G20: =-Inputs!$C$27*(G19+Inputs!$C$29) | H20: =-Inputs!$C$27*(H19+Inputs!$C$29) | I20: =-Inputs!$C$27*(I19+Inputs!$C$29) | J20: =-Inputs!$C$27*(J19+Inputs!$C$29) | K20: =-Inputs!$C$27*(K19+Inputs!$C$29) | M20: =-Inputs!$C$27*(M19+Inputs!$C$29) | Q20: Stock-option SBC is not deductible in Canada, so the taxable base is grossed up by normalised SBC (OE s2.2)
B21: - Other permanent tax differences | C21: =-(Inputs!C41-Inputs!C38*Inputs!$C$27) | D21: =-(Inputs!D41-Inputs!D38*Inputs!$C$27) | E21: =-(Inputs!E41-Inputs!E38*Inputs!$C$27) | F21: =-(Inputs!F41-Inputs!F38*Inputs!$C$27) | G21: =-Inputs!$C$30 | H21: =-Inputs!$C$30 | I21: =-Inputs!$C$30 | J21: =-Inputs!$C$30 | K21: =-Inputs!$C$30 | M21: =-(Inputs!O41-Inputs!O38*Inputs!$C$27) | Q21: Actuals: Note 9 'adjustments to determine taxable income' less the part explained by non-deductible SBC. Forecast: held at the Inputs constant
B22: = OWNERS' EARNINGS | C22: =C19+C20+C21 | D22: =D19+D20+D21 | E22: =E19+E20+E21 | F22: =F19+F20+F21 | G22: =G19+G20+G21 | H22: =H19+H20+H21 | I22: =I19+I20+I21 | J22: =J19+J20+J21 | K22: =K19+K20+K21 | M22: =M19+M20+M21
B23: Owners' earnings margin | C23: =C22/C7 | D23: =D22/D7 | E23: =E22/E7 | F23: =F22/F7 | G23: =G22/G7 | H23: =H22/H7 | I23: =I22/I7 | J23: =J22/J7 | K23: =K22/K7 | M23: =M22/M7
B24: Owners' earnings growth | D24: =D22/C22-1 | E24: =E22/D22-1 | F24: =F22/E22-1 | G24: =G22/F22-1 | H24: =H22/G22-1 | I24: =I22/H22-1 | J24: =J22/I22-1 | K24: =K22/J22-1
B26: Memo -- items deliberately outside owners' earnings:
B27: Reported net income | C27: =Inputs!C42 | D27: =Inputs!D42 | E27: =Inputs!E42 | F27: =Inputs!F42 | M27: =Inputs!O42
B28: Interest income (excluded; the portfolio is added separately in the valuation) | C28: =Inputs!C43 | D28: =Inputs!D43 | E28: =Inputs!E43 | F28: =Inputs!F43 | M28: =Inputs!O43
B29: FX gain / (loss) (normalised to nil) | C29: =Inputs!C44 | D29: =Inputs!D44 | E29: =Inputs!E44 | F29: =Inputs!F44 | M29: =Inputs!O44
B30: Cash flow from operating activities | C30: =Inputs!C45 | D30: =Inputs!D45 | E30: =Inputs!E45 | F30: =Inputs!F45 | M30: =Inputs!O45
B31: Cash conversion: (OCF - capex - after-tax interest) / owners' earnings | C31: =(C30-Inputs!C40-C28*(1-Inputs!$C$27))/C22 | D31: =(D30-Inputs!D40-D28*(1-Inputs!$C$27))/D22 | E31: =(E30-Inputs!E40-E28*(1-Inputs!$C$27))/E22 | F31: =(F30-Inputs!F40-F28*(1-Inputs!$C$27))/F22 | M31: =(M30-Inputs!O40-M28*(1-Inputs!$C$27))/M22 | Q31: OE s2 cash-flow sanity check: owners' earnings do show up as cash
B32: Sanity check: implied H2 FY2026 revenue vs reported H1 FY2026 | G32: =(G7-Inputs!N35)/Inputs!N35-1 | Q32: FC s6: the FY2026E forecast needs only ~2.8% sequential half-on-half revenue growth, of which ~1.2pp is the Q3 FY2026 translation tailwind (Knowledge Store ID 11). H1 FY2026 actual revenue is an input on the Inputs sheet
B34: CHECK: bridge owners' earnings less scenario-engine owners' earnings | F34: =F22-F73 | G34: =G22-CHOOSE(Inputs!$C$17,G73,G112,G151,G190) | H34: =H22-CHOOSE(Inputs!$C$17,H73,H112,H151,H190) | I34: =I22-CHOOSE(Inputs!$C$17,I73,I112,I151,I190) | J34: =J22-CHOOSE(Inputs!$C$17,J73,J112,J151,J190) | K34: =K22-CHOOSE(Inputs!$C$17,K73,K112,K151,K190) | Q34: must be zero in every column -- the two halves of the sheet are the same calculation
B37: SCENARIO ENGINE -- BASE (FC s4/s5 Base: legacy US account -20%/yr, Mexico rollout decelerates, headcount to 26 by FY2030E)
F38: FY2025A | G38: FY2026E | H38: FY2027E | I38: FY2028E | J38: FY2029E | K38: FY2030E
B39: Revenue drivers (linked to Inputs section 7)
B40: US ex-legacy growth (constant currency, USD) | G40: =Inputs!G82 | H40: =Inputs!H82 | I40: =Inputs!I82 | J40: =Inputs!J82 | K40: =Inputs!K82
B41: Legacy largest US account growth (USD) | G41: =Inputs!G83 | H41: =Inputs!H83 | I41: =Inputs!I83 | J41: =Inputs!J83 | K41: =Inputs!K83
B42: Mexico account growth (USD) | G42: =Inputs!G84 | H42: =Inputs!H84 | I42: =Inputs!I84 | J42: =Inputs!J84 | K42: =Inputs!K84
B43: Other international growth (USD) | G43: =Inputs!G85 | H43: =Inputs!H85 | I43: =Inputs!I85 | J43: =Inputs!J85 | K43: =Inputs!K85
B44: Canada growth (CAD) | G44: =Inputs!G86 | H44: =Inputs!H86 | I44: =Inputs!I86 | J44: =Inputs!J86 | K44: =Inputs!K86
B45: US base excluding legacy account (USD) | F45: =Inputs!$C$58 | G45: =F45*(1+G40) | H45: =G45*(1+H40) | I45: =H45*(1+I40) | J45: =I45*(1+J40) | K45: =J45*(1+K40)
B46: Legacy largest US account (USD) | F46: =Inputs!$C$59 | G46: =F46*(1+G41) | H46: =G46*(1+H41) | I46: =H46*(1+I41) | J46: =I46*(1+J41) | K46: =J46*(1+K41)
...

Sheet Valuation
B1: NamSys Inc. -- TERMINAL VALUE AND SUM-OF-THE-PARTS VALUATION
B2: Value per diluted share = PV of FY2026E-FY2030E owners' earnings + PV of the terminal value at October 31 2030 + standalone financial assets - debt-like items, divided by current diluted shares. Deliberately stock-price-blind: no quote or market capitalisation is used anywhere.
B4: A. TERMINAL VALUE AT OCTOBER 31, 2030 (TV s6) -- NOT yet discounted
B5: Scenario | C5: FY2030E owners' earnings | D5: Terminal multiple | E5: Terminal value at 31-Oct-2030
B6: Bull | C6: ='Owners Earnings'!K112 | D6: =Inputs!$C$24 | E6: =C6*D6
B7: Base | C7: ='Owners Earnings'!K73 | D7: =Inputs!$C$21 | E7: =C7*D7 | Q7: TV s6: 12x is the base multiple; the scenario-consistent 'diagonal' pairs 15x with bull and 8x with both bear variants, because the multiple and the earnings path are not independent (TV s1)
B8: Bear - management right-sizes | C8: ='Owners Earnings'!K190 | D8: =Inputs!$C$23 | E8: =C8*D8
B9: Bear - no cost response | C9: ='Owners Earnings'!K151 | D9: =Inputs!$C$23 | E9: =C9*D9
B11: Base-case terminal value across the defensible multiple range (TV s5):
B12: Low end of range | C12: =C7 | D12: =Inputs!$C$20 | E12: =C12*D12
B13: Base | C13: =C7 | D13: =Inputs!$C$21 | E13: =C13*D13
B14: High end of range | C14: =C7 | D14: =Inputs!$C$22 | E14: =C14*D14
B16: B. DISCOUNTING CONVENTION (VAL s2)
B17: The current fiscal year (FY2026, in progress) is t=0 and is NOT discounted. The terminal value is a value AS OF the end of FY2030E, the same time point as the FY2030E cash flow, so it carries the SAME t=4 factor.
G18: FY2026E | H18: FY2027E | I18: FY2028E | J18: FY2029E | K18: FY2030E
B19: Discount period t (years from today) | G19: 0 | H19: 1 | I19: 2 | J19: 3 | K19: 4 | Q19: VAL s2 convention -- editable
B20: Discount factor = 1 / (1 + r)^t | G20: =1/(1+Inputs!$C$7)^G19 | H20: =1/(1+Inputs!$C$7)^H19 | I20: =1/(1+Inputs!$C$7)^I19 | J20: =1/(1+Inputs!$C$7)^J19 | K20: =1/(1+Inputs!$C$7)^K19
B21: Terminal-value discount factor (t = 4, same as FY2030E) | C21: =K20
B23: C. PRESENT VALUE OF FY2026E-FY2030E OWNERS' EARNINGS, BY SCENARIO
B24: The April 30, 2026 balance already contains the operating cash NamSys generated in H1 FY2026. That amount is netted out of the undiscounted t=0 flow so it is counted exactly once (VAL s3.1). It is a realised historical figure, so it is identical in every scenario.
B25: Bull: | E25: PV, sum
B26: Owners' earnings as forecast | G26: ='Owners Earnings'!G112 | H26: ='Owners Earnings'!H112 | I26: ='Owners Earnings'!I112 | J26: ='Owners Earnings'!J112 | K26: ='Owners Earnings'!K112
B27: less H1 FY2026 operating cash already inside the Apr-30-26 balance | G27: =-Inputs!$N$45 | Q27: FSQ2 statements of cash flows, six months ended Apr 30 2026 = 1,497,265 (VAL s3.1)
B28: = Flow discounted at t | G28: =G26+IF(G19=0,G27,0) | H28: =H26 | I28: =I26 | J28: =J26 | K28: =K26
B29: PV of flow | E29: =SUM(G29:K29) | G29: =G28*G20 | H29: =H28*H20 | I29: =I28*I20 | J29: =J28*J20 | K29: =K28*K20
B31: Base: | E31: PV, sum
B32: Owners' earnings as forecast | G32: ='Owners Earnings'!G73 | H32: ='Owners Earnings'!H73 | I32: ='Owners Earnings'!I73 | J32: ='Owners Earnings'!J73 | K32: ='Owners Earnings'!K73
B33: less H1 FY2026 operating cash already inside the Apr-30-26 balance | G33: =-Inputs!$N$45 | Q33: FSQ2 statements of cash flows, six months ended Apr 30 2026 = 1,497,265 (VAL s3.1)
B34: = Flow discounted at t | G34: =G32+IF(G19=0,G33,0) | H34: =H32 | I34: =I32 | J34: =J32 | K34: =K32
B35: PV of flow | E35: =SUM(G35:K35) | G35: =G34*G20 | H35: =H34*H20 | I35: =I34*I20 | J35: =J34*J20 | K35: =K34*K20
B37: Bear - management right-sizes: | E37: PV, sum
B38: Owners' earnings as forecast | G38: ='Owners Earnings'!G190 | H38: ='Owners Earnings'!H190 | I38: ='Owners Earnings'!I190 | J38: ='Owners Earnings'!J190 | K38: ='Owners Earnings'!K190
B39: less H1 FY2026 operating cash already inside the Apr-30-26 balance | G39: =-Inputs!$N$45 | Q39: FSQ2 statements of cash flows, six months ended Apr 30 2026 = 1,497,265 (VAL s3.1)
B40: = Flow discounted at t | G40: =G38+IF(G19=0,G39,0) | H40: =H38 | I40: =I38 | J40: =J38 | K40: =K38
B41: PV of flow | E41: =SUM(G41:K41) | G41: =G40*G20 | H41: =H40*H20 | I41: =I40*I20 | J41: =J40*J20 | K41: =K40*K20
B43: Bear - no cost response: | E43: PV, sum
B44: Owners' earnings as forecast | G44: ='Owners Earnings'!G151 | H44: ='Owners Earnings'!H151 | I44: ='Owners Earnings'!I151 | J44: ='Owners Earnings'!J151 | K44: ='Owners Earnings'!K151
B45: less H1 FY2026 operating cash already inside the Apr-30-26 balance | G45: =-Inputs!$N$45 | Q45: FSQ2 statements of cash flows, six months ended Apr 30 2026 = 1,497,265 (VAL s3.1)
B46: = Flow discounted at t | G46: =G44+IF(G19=0,G45,0) | H46: =H44 | I46: =I44 | J46: =J44 | K46: =K44
B47: PV of flow | E47: =SUM(G47:K47) | G47: =G46*G20 | H47: =H46*H20 | I47: =I46*I20 | J47: =J46*J20 | K47: =K46*K20
...
