Workbook

Sheet 1 Earnings
A1: Boyd Group Services (BYD.TO) - Sheet 1: Owners' Earnings, historical and forecast
A2: US$ millions unless stated. Python sources: owners_earnings_roic.py (historical), forecast_earnings.py (forecast). Share price not used anywhere.
A3: Input (change me) | B3: Linked from elsewhere (do not overwrite) | F3: Black = formula
A5: INPUTS
A6: 1.1 Reported figures (US$M, from filings) | B6: FY2023 | C6: FY2024 | D6: FY2025 | E6: H1-2025 | F6: H1-2026 | L6: Source / explanation
A7: Sales | B7: 2945.988 | C7: 3070.342 | D7: 3142.794 | E7: 1558.73 | F7: 2010.328 | L7: FY2023 AFS / FY2025 AFS statements of earnings; H1 columns from Q2FY26 interim statements (owners_earnings_roic.py l.30-37)
A8: Adjusted EBITDA, Q3-2025 | B8: 98.366 | L8: Q2FY26 MD&A quarterly table, line 350
A9: Adjusted EBITDA, Q4-2025 | B9: 103.609 | L9: Q2FY26 MD&A quarterly table, line 350
A10: Adjusted EBITDA, Q1-2026 | B10: 122.385 | L10: Q2FY26 MD&A quarterly table, line 350
A11: Adjusted EBITDA, Q2-2026 | B11: 135.932 | L11: Q2FY26 MD&A quarterly table, line 350
A12: Adjusted EBITDA (company-reported) | B12: 368.247 | C12: 334.819 | D12: 376.306 | E12: =D12-B8-B9 | F12: =B10+B11 | L12: FY2023 MD&A l.282; FY2024 MD&A l.198; FY2025 MD&A l.209. H1-2025 = FY2025 less Q3 and Q4; H1-2026 = Q1 + Q2
A13: Lease principal repaid - property | B13: 95.441 | C13: 103.888 | D13: 111.142 | E13: 54.892 | F13: 72.637 | L13: Financing section of cash flow statement (FY2025 AFS l.298; Q2FY26 FS l.167)
A14: Lease principal repaid - vehicle & equipment | B14: 3.863 | C14: 5.283 | D14: 5.594 | E14: 2.815 | F14: 2.901 | L14: FY2025 AFS l.299; Q2FY26 FS l.168
A15: Lease interest paid - property | B15: 31.328 | C15: 39.464 | D15: 44.095 | E15: 21.555 | F15: 31.872 | L15: FY2025 AFS l.301; Q2FY26 FS l.171
A16: Lease interest paid - vehicle & equipment | B16: 0.728 | C16: 1.021 | D16: 0.73 | E16: 0.462 | F16: 0.531 | L16: FY2025 AFS cash flows; Q2FY26 FS l.172. FY2025 principal + interest ties to AFS Note 17 repayments 161,561
A17: Equipment purchases & facility improvements (actual) | B17: 57.482 | C17: 77.333 | D17: 54.306 | E17: 25.765 | F17: 24.802 | L17: Investing section of cash flow statement; memo only (maintenance capex is modelled at % of sales)
A18: Software purchases and licensing (actual) | B18: 1.684 | C18: 3.124 | D18: 8.094 | E18: 3.132 | F18: 0.936 | L18: Investing section of cash flow statement
A19: Income taxes paid (cash) | B19: 27.909 | C19: 12.295 | D19: 3.669 | E19: 2.555 | F19: 3.26 | L19: Supplemental CFS line: FY2023 AFS l.297, FY2024 AFS l.300, FY2025 AFS l.318, Q2FY26 l.190
A20: Acquisition & transformational cost initiatives (actual) | B20: 4.346 | C20: 9.879 | D20: 30.488 | E20: 13.773 | F20: 31.264 | L20: Statement of earnings line (FY2023 label: 'Acquisition and transaction costs')
A21: Cash flow from operations (reported) | B21: 357.545 | C21: 313.325 | D21: 352.989 | E21: 170.593 | F21: 224.591 | L21: Statements of cash flows. Boyd reports all interest and lease principal in financing (AFS Note 2u)
A22: Changes in non-cash working capital (in CFO) | B22: 19.072 | C22: -5.909 | D22: 5.752 | E22: 18.791 | F22: -6.375 | L22: Statements of cash flows; used only in the CFO reconciliation
A23: Equity-settled share-based payment added back in CFO | B23: 0 | C23: 0.928 | D23: 4.319 | E23: 1.877 | F23: 4.689 | L23: Statements of cash flows (FY2023 not separately disclosed)
A24: Other non-cash items added back in CFO | B24: 0.444 | C24: 1.033 | D24: 2.928 | E24: 0.001 | F24: 3.425 | L24: Mainly losses on disposal, already inside Adjusted EBITDA
A25: Current income tax expense (statement of earnings) | B25: 25.872 | C25: 7.667 | D25: 5.828 | E25: 10.634 | F25: 4.201 | L25: Statement of earnings; used only in the CFO reconciliation
A27: 1.2 Owners' Earnings normalization assumptions | B27: Value | L27: Source / explanation
A28: Maintenance capex, % of sales | B28: 0.017 | L28: Mgmt guidance 1.6-1.8% of sales ex network tech & new locations, midpoint (FY2025 MD&A l.526; Q2FY26 MD&A l.102). Largest single judgment in historical OE
A29: Normalized recurring acquisition cost (US$M/yr) | B29: 5 | L29: JUDGMENT: FY2022 actual 1.7, FY2023 actual 4.3 bracket the ordinary-course level (owners_earnings_and_roic.md sec 2.5)
A30: Normalized tax rate | B30: 0.265 | L30: Combined statutory rate 26.66% (2025) / 26.53% (2024), FY2025 AFS Note 10a
A32: 1.3 Forecast inputs, common to all cases | B32: Value | F32: 2026E | G32: 2027E | H32: 2028E | I32: 2029E | J32: 2030E | K32: 2031E | L32: Source / explanation
A33: FY2025 pro-forma sales (2025 acquisitions annualized) | B33: 3235.845 | L33: FY2025 AFS l.713: revenue if 2025 acquisitions owned from Jan-1-2025. Starting legacy-Boyd sales base
A34: Project 360 savings already inside FY2025 EBITDA | B34: 40 | L34: ~$40M realized in 2025 (FY2025 MD&A l.111); stripped out of the base margin, added back as savings
A35: Cumulative cost-program savings vs 2024 base (gross) | F35: 105 | G35: 116.7 | H35: 128.3 | I35: 140 | J35: 140 | K35: 140 | L35: $40M 2025, +$65M 2026, +$35M ratably 2027-29 (Q2FY26 MD&A l.70, l.221)
A36: Revenue booked in 2025 by locations acquired in 2025 | B36: 31.508 | L36: FY2025 AFS l.713
A37: Locations acquired in 2025 (number) | B37: 43 | L37: FY2025 AFS l.663
A38: Joe Hudson's pre-deal sales (TTM Jun-25) | B38: 722 | L38: JH release l.14
A39: Joe Hudson's pre-synergy Adj. EBITDA margin (pre-rent) | B39: 0.144 | L39: JH release l.14
A40: Joe Hudson's FY2026E sales (conversion-disrupted) | B40: 700 | L40: ASSUMPTION: H1'26 $342.6M x2 plus modest H2 recovery (Q2FY26 MD&A l.72, l.291)
A41: Joe Hudson's FY2026E margin | B41: 0.13 | L41: ASSUMPTION: ~$22M lost sales x ~46% gross margin = ~1.4pp below pre-deal
A42: Operating leverage: margin change per 1pp of SSS above breakeven | B42: 0.3 | L42: CALIBRATED: mgmt 2-4% SSS -> ~+20bp/yr (FY2025 call l.281); FY2024 SSS -1.8% -> margin -1.6pp
A43: Operating leverage: breakeven SSS | B43: 0.023 | L43: CALIBRATED (as above)
...

Sheet 2 Terminal Value
A1: Boyd Group Services (BYD.TO) - Sheet 2: Terminal value at end-2031 (undiscounted)
A2: US$ millions. TV = EV/EBITDA-after-rent multiple x FY2031E EBITDA after rent + same multiple x ramp gap. Python source: terminal_value.py. Multiples from collision-repair deal evidence, not Boyd's share price.
A3: Input (change me) | B3: Linked from elsewhere (do not overwrite) | F3: Black = formula
A5: INPUTS
A6: 2.1 Exit multiple (EV / EBITDA after rent) | B6: Bear | C6: Base | D6: No growth | E6: Bull | L6: Source / explanation
A7: Chosen exit multiple | B7: 6 | C7: 8.5 | D7: 8.5 | E7: 10 | L7: JUDGMENT within the deal evidence in 2.4 (terminal_value.md sec 6-7). No growth = base (same network)
A9: 2.2 Steady-state assumptions (value-driver cross-check only) | B9: Bear | C9: Base | D9: No growth | E9: Bull | L9: Source / explanation
A10: Growth without new capital (claims volume + repair cost) | B10: 0.005 | C10: 0.02 | D10: =C10 | E10: 0.025 | L10: Bear -1.5+2.0; Base -1.0+3.0; Bull capped so total g = 3% (impairment test)
A11: Growth from share gains needing new capacity | B11: 0.005 | C11: 0.005 | D11: 0 | E11: 0.005 | L11: None in the no-growth-capex case
A12: After-tax OE yield on new capacity | B12: 0.045 | C12: 0.077 | D12: =C12 | E12: 0.108 | L12: Mature unit OE yield (forecast_earnings.md sec 6.4)
A14: 2.3 Other cross-check inputs | B14: Value | L14: Source / explanation
A15: Boyd impairment test: terminal growth | B15: 0.03 | L15: FY2025 AFS l.966
A16: Boyd impairment test: WACC low | B16: 0.07 | L16: FY2025 AFS l.966
A17: Boyd impairment test: WACC high | B17: 0.09 | L17: FY2025 AFS l.966
A18: Cross-check discount rate (midpoint of impairment WACC) | B18: =AVERAGE(B16,B17) | L18: Formula. Used only for value-driver check and to compound 2026-31 cash in 3.4
A19: Management Adj. EBITDA margin target | B19: 0.14 | L19: Q2FY26 MD&A (14% target); used in the margin-normalization check
A20: Forecast weight - Bear | B20: ='1 Earnings'!B64 | L20: Linked to sheet 1
A21: Forecast weight - Base | B21: ='1 Earnings'!B65 | L21: Linked to sheet 1
A22: Forecast weight - Bull | B22: ='1 Earnings'!B66 | L22: Linked to sheet 1
A24: 2.4 Collision-repair valuation evidence (EV / EBITDA after rent) | B24: Low | C24: High | D24: Mid | L24: Source / explanation
A25: Single shops | B25: 3 | C25: 5 | D25: =AVERAGE(B25,C25) | L25: Knowledge Store IDs 11, 28
A26: Small / medium MSOs bought by consolidators | B26: 5 | C26: 7 | D26: =AVERAGE(B26,C26) | L26: Knowledge Store IDs 20, 28
A27: Market average, 2025 (weak claims year) | B27: 7 | C27: 7 | D27: =AVERAGE(B27,C27) | L27: Knowledge Store IDs 19
A28: MSOs with strong DRP relationships | B28: 7 | C28: 10 | D28: =AVERAGE(B28,C28) | L28: Knowledge Store IDs 11
A29: Platform-grade MSOs | B29: 8 | C29: 12 | D29: =AVERAGE(B29,C29) | L29: Knowledge Store IDs 11
A30: PE platform recap (illustrative) | B30: 10 | C30: 10 | D30: =AVERAGE(B30,C30) | L30: Knowledge Store IDs 21
A31: PE platforms raising capital, 2024 | B31: 12 | C31: 14 | D31: =AVERAGE(B31,C31) | L31: Knowledge Store IDs 20, 21
A32: Joe Hudson's to TSG, 2019 ('north of 13x') | B32: 13 | C32: 13 | D32: =AVERAGE(B32,C32) | L32: Knowledge Store IDs 25
A33: Joe Hudson's to Boyd, 2025, run-rate pre-synergy | B33: 13.3 | C33: 13.3 | D33: =AVERAGE(B33,C33) | L33: JH release l.43
A34: Joe Hudson's to Boyd, 2025, run-rate + synergies | B34: 9.3 | C34: 9.3 | D34: =AVERAGE(B34,C34) | L34: JH release l.43
A36: 2.5 Joe Hudson's deal (fetched_docs/boyd_joe_hudsons_acquisition_announcement.md) | B36: Value | L36: Source / explanation
A37: Purchase price | B37: 1300 | L37: line 13
A38: Expected tax benefits | B38: 150 | L38: line 43 ('approximately $150 million'); also used as a standalone asset on sheet 3
A39: JHCC Adj. EBITDA, US GAAP (after rent), TTM | B39: 63 | L39: line 37
A40: JHCC Adj. EBITDA, IFRS-like (pre-rent), TTM | B40: 104 | L40: line 37
A41: Disclosed multiple, run-rate pre-synergy | B41: 13.3 | L41: line 43
A42: Disclosed multiple, run-rate + synergies | B42: 9.3 | L42: line 43
A43: Disclosed synergies, low | B43: 35 | L43: line 45
A44: Disclosed synergies, high | B44: 45 | L44: line 45
A46: 2.6 AMA Group (ASX: AMA), listed pure-play, A$M | B46: Value | L46: Source / explanation
...

Sheet 3 SOTP Valuation
A1: Boyd Group Services (BYD.TO) - Sheet 3: Sum-of-the-parts valuation per share
A2: US$ millions unless stated. Value = PV(2026-31 distributable cash) + PV(terminal value) + standalone assets - debt. Python source: valuation.py. Trading price not used.
A3: Input (change me) | B3: Linked from elsewhere (do not overwrite) | F3: Black = formula
A5: INPUTS
A6: 3.1 Valuation settings and case weights | B6: Value | L6: Source / explanation
A7: Discount rate | B7: 0.1 | L7: Task requirement (valuation.py ValuationSettings)
A8: Valuation year (t = 0, not discounted) | B8: 2026
A9: Terminal year (TV sits at end of this year) | B9: 2031
A10: Case weights | B10: Bear | C10: Base | D10: No growth | E10: Bull | L10: Source / explanation
A11: Weight in headline value | B11: 0.25 | C11: 0.25 | D11: 0.25 | E11: 0.25 | L11: No growth shares the base drivers, so takes half the base's 50% (valuation.md sec 1)
A13: 3.2 H1-2026 actuals (to strip realized cash out of FY2026E) | B13: Value | L13: Source / explanation
A14: H1-2026 Adjusted EBITDA | B14: ='1 Earnings'!F12 | L14: Linked to sheet 1
A15: H1-2026 cash rent | B15: ='1 Earnings'!F13+'1 Earnings'!F14+'1 Earnings'!F15+'1 Earnings'!F16 | L15: Linked to sheet 1
A16: H1-2026 net growth spend (acquisitions & development less sale-leasebacks, ex-JH) | B16: 32.9 | L16: forecast_earnings.md sec 6.1a, H1-2026 row
A18: 3.3 Balance sheet at Jun-30-2026 (Q2FY26 FS) | B18: Value | L18: Source / explanation
A19: Cash | B19: 22.969 | L19: Balance sheet
A20: Operating cash requirement | B20: 25 | L20: owners_earnings_and_roic.md sec 4: cash capped at $25M as operating
A21: Revolver + swing line (net of financing costs) | B21: 285.253 | L21: Note 11
A22: Term Loan A (net of financing costs) | B22: 124.963 | L22: Note 11
A23: Seller notes (deferred acquisition consideration) | B23: 8.606 | L23: Note 11
A24: Senior notes 2030, US$ (C$525M principal) | B24: 369.443 | L24: Note 12
A25: Senior notes 2033, US$ (C$275M principal) | B25: 193.517 | L25: Note 12
A26: Dividends payable | B26: 3.056 | L26: Balance sheet
A27: Cross-currency swaps - asset | B27: 4.305 | L27: Balance sheet
A28: Cross-currency swaps - liability | B28: 3.003 | L28: Balance sheet
A29: Memo: lease liabilities, current (NOT deducted) | B29: 159.574 | L29: Rent is charged in full inside Owners' Earnings; deducting would double count
A30: Memo: lease liabilities, non-current (NOT deducted) | B30: 891.311
A31: Memo: deferred tax liability (NOT deducted) | B31: 104.318
A32: Memo: deferred tax asset | B32: 10.051
A34: 3.4 Goodwill & intangible tax shields (value outside OE, which is taxed at full rate) | B34: Value | L34: Source / explanation
A35: Joe Hudson's tax benefits, Boyd's estimate | B35: ='2 Terminal Value'!B38 | L35: Linked to sheet 2 (JH release l.43)
A36: Joe Hudson's goodwill (book) | B36: 521.76 | L36: Q2FY26 FS acquisition table l.249-258
A37: Joe Hudson's customer relationships | B37: 700 | L37: Same table
A38: Joe Hudson's brand | B38: 0.5 | L38: Same table
A39: Joe Hudson's intellectual property | B39: 0.3 | L39: Same table
A40: Legacy goodwill, Dec-2025 | B40: 702.46 | L40: Q2FY26 FS l.28, Dec-25 column
A41: Legacy intangibles (net), Dec-2025 | B41: 356.347 | L41: Same
A42: Other 2026 acquisitions: goodwill | B42: 7.208 | L42: Q2FY26 FS acquisition table, 'Other acquisitions'
A43: Other 2026 acquisitions: customer relationships | B43: 5.496 | L43: Same
A44: Other 2026 acquisitions: non-competes | B44: 0.245 | L44: Same
...
